package exception_finally;

public class Exception_Finally {
    public static void main(String[] args) {
        int arr[]=new int[3];
        try{
          arr[4]=20;
            System.out.println("Access alement three:"+arr[4]);
        }catch(ArrayIndexOutOfBoundsException e){
            System.out.println(e);
        }finally{
          arr[1]=122;
            System.out.println("First element value is:"+arr[1]);
            System.out.println("the finally Stetament is Excute...");
        }
    }
    
}
